<?xml version="1.0"?>
<robot xmlns:xacro="http://www.ros.org/wiki/xacro" name="robot4">
<xacro:include filename="$(find robot_urdf)/urdf/robot.gazebo"/>
					
	<xacro:property name="length_wheel" value="0.04" />
	<xacro:property name="radius_wheel" value="0.1" />

	<xacro:macro name="default_inertial" params="mass">
               <inertial>
                       <mass value="${mass}" />
                       <origin rpy="0 1.5707 1.5707" xyz="0 0 0"/>
                       <inertia ixx="0.000526666666667" ixy="0" ixz="0" iyy="0.000526666666667" iyz="0" izz="0.001"/>
               </inertial>
	</xacro:macro>

    <xacro:macro name="wheel_geometry">
		<geometry>
       			<cylinder length="${length_wheel}" radius="${radius_wheel}"/>
     	</geometry>
	</xacro:macro>
	
<!--################################# COLOUR #####################################-->

	
  <material name="black">
    <color rgba="0.0 0.0 0.0 1.0"/>
  </material>
  <material name="blue">
    <color rgba="0.203125 0.23828125 0.28515625 1.0"/>
  </material>
  <material name="green">
    <color rgba="0.0 0.8 0.0 1.0"/>
  </material>
  <material name="grey">
    <color rgba="0.2 0.2 0.2 1.0"/>
  </material>
  <material name="orange">
    <color rgba="1.0 0.423529411765 0.0392156862745 1.0"/>
  </material>
  <material name="brown">
    <color rgba="0.870588235294 0.811764705882 0.764705882353 1.0"/>
  </material>
  <material name="red">
    <color rgba="0.80078125 0.12890625 0.1328125 1.0"/>
  </material>
  <material name="white">
    <color rgba="1.0 1.0 1.0 1.0"/>
  </material>
  
  <!--################################# BASE #####################################--> 
  

	  <link name="link_chassis">
    <!-- pose and inertial -->
    <pose>0 0 0.1 0 0 0</pose>
    <inertial>
      <mass value="10"/>
      <origin rpy="0 0 0" xyz="0 0 0.1"/>
      <inertia ixx="0.0395416666667" ixy="0" ixz="0" iyy="0.106208333333" iyz="0" izz="0.106208333333"/>
    </inertial>
    
    <!-- body -->
    <collision name="collision_chassis">
      <origin
        xyz="0 0 0"
        rpy="1.5707963267949 0 3.14" />
      <geometry>
        <mesh filename="package://robot_urdf/meshes/robot_base.stl" />
      </geometry>
    </collision>
    
    <visual>
      <origin
        xyz="0 0 0"
        rpy="1.5707963267949 0 3.14" />
      <geometry>
        <mesh filename="package://robot_urdf/meshes/robot_base.stl" />
      </geometry>
      <material
        name="">
        <color
          rgba="0.79216 0.81961 0.93333 1" />
      </material>
    </visual>
    
    
    
    
    <!-- caster front -->
    <collision name="caster_front_collision">
      <origin rpy=" 0 0 0" xyz="0.35 0 -0.05"/>
      <geometry>
        <sphere radius="0.05"/>
      </geometry>
    </collision>
    <visual name="caster_front_visual">
      <origin rpy=" 0 0 0" xyz="0.2 0 -0.05"/>
      <geometry>
        <sphere radius="0.05"/>
      </geometry>
    </visual>
  </link>
  
  
  

   <link name="link_back_right_wheel">
    <xacro:default_inertial mass="0.2"/>
    <collision name="link_back_right_wheel_collision">
      <origin
        xyz="0 0 0"
        rpy="1.5707963267949 0 3.14" />
      <geometry>
        <mesh filename="package://robot_urdf/meshes/wheel.stl" />
      </geometry>
    </collision>
    <visual>
      <origin
        xyz="0 0 0"
        rpy="1.5707963267949 0 3.14" />
      <geometry>
        <mesh filename="package://robot_urdf/meshes/wheel.stl" />
      </geometry>
      <material
        name="">
        <color
          rgba="0.79216 0.81961 0.93333 1" />
      </material>
    </visual>
  </link>
  

   <link name="link_back_left_wheel">
    <xacro:default_inertial mass="0.2"/>
    <collision name="link_back_left_wheel_collision">
      <origin
        xyz="0 0 0"
        rpy="1.5707963267949 0 0" />
      <geometry>
        <mesh filename="package://robot_urdf/meshes/wheel.stl" />
      </geometry>
    </collision>
    <visual>
      <origin
        xyz="0 0 0"
        rpy="1.5707963267949 0 0" />
      <geometry>
        <mesh filename="package://robot_urdf/meshes/wheel.stl" />
      </geometry>
      <material
        name="">
        <color
          rgba="0.79216 0.81961 0.93333 1" />
      </material>
    </visual>
  </link>


   <link name="link_front_left_wheel">
    <xacro:default_inertial mass="0.2"/>
    <collision name="link_front_left_wheel_collision">
      <origin rpy="0 0 0" xyz="0 0 0"/>
      <xacro:wheel_geometry />
    </collision>
    <visual>
      <origin
        xyz="0 0 0"
        rpy="1.5707963267949 0 0" />
      <geometry>
        <mesh filename="package://robot_urdf/meshes/wheel.stl" />
      </geometry>
      <material
        name="">
        <color
          rgba="0.79216 0.81961 0.93333 1" />
      </material>
    </visual>
  </link>
  
   <link name="link_front_right_wheel">
    <xacro:default_inertial mass="0.2"/>
    <collision name="link_front_right_wheel_collision">
      <origin rpy="0 0 0" xyz="0 0 0"/>
      <xacro:wheel_geometry />
    </collision> 
    <visual>
      <origin
        xyz="0 0 0"
        rpy="1.5707963267949 0 3.14" />
      <geometry>
        <mesh filename="package://robot_urdf/meshes/wheel.stl" />
      </geometry>
      <material
        name="">
        <color
          rgba="0.79216 0.81961 0.93333 1" />
      </material>
    </visual>
   </link>  


  

  
  
  <joint name="joint_back_right_wheel" type="continuous">
    <origin rpy="0 0 0" xyz="-0.15 0.26 0"/>
    <child link="link_back_right_wheel"/>
    <parent link="link_chassis"/>
    <axis rpy="0 0 0" xyz="0 1 0"/>
    <limit effort="100" velocity="10"/>
    <joint_properties damping="1.0" friction="1.0"/>
  </joint>
  
  
  <joint name="joint_back_left_wheel" type="continuous">
    <origin rpy="0 0 0" xyz="-0.15 -0.26 0"/>
    <child link="link_back_left_wheel"/>
    <parent link="link_chassis"/>
    <axis rpy="0 0 0" xyz="0 1 0"/>
    <limit effort="100" velocity="10"/>
    <joint_properties damping="1.0" friction="1.0"/>
  </joint>
  
  <joint name="joint_front_right_wheel" type="continuous">
    <origin rpy="0 0 0" xyz="0.15 0.26 0"/>
    <child link="link_front_right_wheel"/>
    <parent link="link_chassis"/>
    <axis rpy="0 0 0" xyz="0 1 0"/>
    <limit effort="100" velocity="10"/>
    <joint_properties damping="1.0" friction="1.0"/>
  </joint>
  
  
  <joint name="joint_front_left_wheel" type="continuous">
    <origin rpy="0 0 0" xyz="0.15 -0.26 0"/>
    <child link="link_front_left_wheel"/>
    <parent link="link_chassis"/>
    <axis rpy="0 0 0" xyz="0 1 0"/>
    <limit effort="100" velocity="10"/>
    <joint_properties damping="1.0" friction="1.0"/>
  </joint> 
  
  
 

  
 <!--############################## ARM  ########################################-->
 
  
  
  

<link name="arm_base">
  	<inertial>
  		<mass value="0.5"/>
  		<origin xyz="0 0 0" rpy="0 0 0" />
  		<inertia ixx="0" ixy="0" ixz="0" iyy="0" iyz="0" izz="0"/>
  	</inertial>
    <visual>
      <origin
        xyz="0 0 0"
        rpy="0 0 1.5707963267949" />
      <geometry>
	       <mesh filename="package://robot_urdf/meshes/arm_base.stl" />
      </geometry>
    </visual>
    
  	<collision>
  	  <origin xyz="0 0 0.1" rpy="0 0 0"/>
      <geometry>
        <box size="0.1 0.1 0.1"/>
      </geometry>
  	</collision>
</link> 

  <joint name="base_to_arm_base" type="continuous">
                <limit effort="100" velocity="0.5"/>
                <joint_properties damping="0" friction="1.0"/>
		<parent link="link_chassis"/>
		<child link="arm_base"/>
		<axis xyz="0 0 1"/>
		<origin xyz="0 0 0.16"/>
  </joint>


 <link name="arm_1">
  	<inertial>
  		<mass value="0.1"/>
  		<origin xyz="0 0 0" rpy="0 0 0" />
  		<inertia ixx="0" ixy="0" ixz="0" iyy="0" iyz="0" izz="0"/>
  	</inertial>
  	<collision>
  	  <origin xyz="0 0 0.25" rpy="0 0 0"/>
      <geometry>
        <cylinder length="0.5" radius="0.03"/>
      </geometry>
  	</collision>
  	<visual>
  	  <origin xyz="0 0 0.25" rpy="0 0 0"/>
      <geometry>
       <cylinder length="0.5" radius="0.03"/>
      </geometry>
      <material name="red" />
  	</visual>
  </link>

  <joint name="arm_1_to_arm_base" type="revolute">
		<parent link="arm_base"/>
		<child link="arm_1"/>
		<axis xyz="0 1 0"/>
		<origin xyz="0 -0.1 0.15"/>
		<limit effort ="100.0" lower="-1.5707963267949" upper="1.5707963267949" velocity="0.5"/>
 </joint> 
 
 
 
<link name="arm_2">
  	<inertial>
  		<mass value="0.02"/>
  		<origin xyz="0 0 0" rpy="0 0 0" />
  		<inertia ixx="0" ixy="0" ixz="0" iyy="0" iyz="0" izz="0"/>
  	</inertial>
  	<collision>
  	  <origin xyz="0.06 0 0.15" rpy="0 0 0"/>
      <geometry>
        <cylinder length="0.5" radius="0.03"/>
      </geometry>
  	</collision>
  	<visual>
  	  <origin xyz="0.06 0 0.15" rpy="0 0 0"/>
      <geometry>
        <cylinder length="0.5" radius="0.03"/>
      </geometry>
      <material name="red" />
  	</visual>
  </link>

   <joint name="arm_2_to_arm_1" type="revolute">
		<parent link="arm_1"/>
		<child link="arm_2"/>
		<axis xyz="0 2 0"/>
		<origin xyz="-0.055 0.08 0.5"/>
		<limit effort ="100.0" lower="-1.5707963267949" upper="1.5707963267949" velocity="0.5"/>
</joint>



 <link name="arm_3">
  	<inertial>
  		<mass value="0.015"/>
  		<origin xyz="0 0 0" rpy="0 0 0" />
  		<inertia ixx="0" ixy="0" ixz="0" iyy="0" iyz="0" izz="0"/>
  	</inertial>
  	<collision>
  	  <origin xyz="0.06 0 0.15" rpy="0 0 1.5707963267949"/>
      <geometry>
        <box size="0.06 0.6 0.06"/>
      </geometry>
  	</collision>
  	<visual>
  	  <origin xyz="0.06 0 0.15" rpy="0 0 1.5707963267949"/>
      <geometry>
        <box size="0.05 0.7 0.05"/>
      </geometry>
      <material name="red" />
  	</visual>
  </link>

   <joint name="arm_3_to_arm_2" type="prismatic">
		<parent link="arm_2"/>
		<child link="arm_3"/>
		<axis xyz="1 0  0"/>
		<origin xyz="0.17 0  0.25"/>
		<limit effort ="100.0" lower="-0.2" upper="1" velocity="0.5"/>

</joint>



<link name="arm_4">
  	<inertial>
  		<mass value="0"/>
  		<origin xyz="0 0 0" rpy="0 0 0" />
  		<inertia ixx="0" ixy="0" ixz="0" iyy="0" iyz="0" izz="0"/>
  	</inertial>
  	<collision>
  	  <origin xyz="0 0 0.15" rpy="0 0 1.5707963267949"/>
      <geometry>
        <box size="0 0 0"/>
      </geometry>
  	</collision>
  	<visual>
  	  <origin xyz="0.06 0 0.15" rpy="0 0 1.5707963267949"/>
      <geometry>
        <box size="0.09 0.6 0.09"/>
      </geometry>
      <material name="red" />
  	</visual>
  </link>

   <joint name="arm_4_to_arm_2" type="fixed">
		<parent link="arm_2"/>
		<child link="arm_4"/>
		<axis xyz="2 0  0"/>
		<origin xyz="+0.20 0  0.25"/>
		
</joint>



<!--############################## ARM_CONTROL  ########################################-->
	
	
	

 <transmission name="base_to_arm_base_trans">
	<type>transmission_interface/SimpleTransmission</type>
	<joint name="base_to_arm_base">
		<hardwareInterface>hardware_interface/EffortJointInterface</hardwareInterface>
	</joint>
	<actuator name="motor3">
		<hardwareInterface>hardware_interface/EffortJointInterface</hardwareInterface>
		<mechanicalInterface>1</mechanicalInterface>
	</actuator>
</transmission>      

<transmission name="arm_1_to_arm_base_trans">
	<type>transmission_interface/SimpleTransmission</type>
	<joint name="arm_1_to_arm_base">
		<hardwareInterface>hardware_interface/EffortJointInterface</hardwareInterface>
	</joint>
	<actuator name="motor1">
		<hardwareInterface>hardware_interface/EffortJointInterface</hardwareInterface>
		<mechanicalInterface>1</mechanicalInterface>
	</actuator>
</transmission>


<transmission name="arm_2_to_arm_1_trans">
	<type>transmission_interface/SimpleTransmission</type>
	<joint name="arm_2_to_arm_1">
		<hardwareInterface>hardware_interface/EffortJointInterface</hardwareInterface>
	</joint>
	<actuator name="motor2">
		<hardwareInterface>hardware_interface/EffortJointInterface</hardwareInterface>
		<mechanicalInterface>1</mechanicalInterface>
	</actuator>
</transmission>

<transmission name="arm_3_to_arm_2_trans">
	<type>transmission_interface/SimpleTransmission</type>
	<joint name="arm_3_to_arm_2">
		<hardwareInterface>hardware_interface/EffortJointInterface</hardwareInterface>
	</joint>
	<actuator name="motor4">
		<hardwareInterface>hardware_interface/EffortJointInterface</hardwareInterface>
		<mechanicalInterface>1</mechanicalInterface>
	</actuator>
</transmission>


<!--############################## CAMERA########################################-->



   <link name="camera_front_link">
	    <collision>
	      <origin xyz="0 0 0.025" rpy="0 0 0"/>
	      <geometry>
		<box size="0 0 0"/>
	      </geometry>
	    </collision>
	    <visual>
	      <origin xyz="0 0 0.025" rpy="0 0 0"/>
	      <geometry>
		<box size="0.05 0.05 0.05"/>
	      </geometry>
	      <material name="orange">
		<color rgba="1 0 0 1"/>
	      </material>
	    </visual>
	    <inertial>
	      <mass value="0" />
	      <origin xyz="0 0 0" rpy="0 0 0"/>
	      <inertia ixx="0" ixy="0" ixz="0" iyy="0" iyz="0" izz="0" />
	    </inertial> 
  </link>
  
  <joint name="camera_front_joint" type="fixed">
	    <axis xyz="0 1 0" />
	    <origin xyz="0.45 0 0.1" rpy="0 0 0"/>
	    <parent link="arm_3"/>
	    <child link="camera_front_link"/> 
	 </joint>
 




<!--############################## HOKUYO_LINK ########################################-->


  
   <link name="hokuyo_link">
	    <collision>
	      <origin xyz="0 0 0.025" rpy="0 0 0"/>
	      <geometry>
		<box size="0.05 0.09 0.05"/>
	      </geometry>
	    </collision>
	    <visual>
	      <origin xyz="0 0 0.025" rpy="0 0 0"/>
	      <geometry>
		<box size="0.05 0.09 0.05"/>
	      </geometry>
	      <material name="red">
		<color rgba="1 0 0 1"/>
	      </material>
	    </visual>
	    <inertial>
	      <mass value="1e-5" />
	      <origin xyz="0 0 0" rpy="0 0 0"/>
	      <inertia ixx="1e-6" ixy="0" ixz="0" iyy="1e-6" iyz="0" izz="1e-6" />
	    </inertial> 
 	 </link>
 	 
 	 <joint name="hokuyo_joint" type="fixed">
	    <axis xyz="0 1 0" />
	    <origin xyz="0.35 0 0.08" rpy="0 0 0"/>
	    <parent link="link_chassis"/>
	    <child link="hokuyo_link"/> 
	 </joint>



</robot>
